Workbook

Sheet P&L
B1: YTD | D1: Jan 2026 | F1: Feb 2026 | H1: Mar 2026 | J1: Apr 2026 | L1: May 2026 | N1: Jun 2026 | P1: Jul 2026 | R1: Aug 2026 | T1: Sep 2026 | V1: Oct 2026 | X1: Nov 2026 | Z1: Dec 2026
A2: Company : Sai Dham | B2: Amount | C2: Amount | D2: Amount | E2: Amount | F2: Amount | G2: Amount | H2: Amount | I2: Amount | J2: Amount | K2: Amount | L2: Amount | M2: Amount | N2: Amount | O2: Amount | P2: Amount | Q2: Amount | R2: Amount | S2: Amount | T2: Amount | U2: Amount | V2: Amount | W2: Amount | X2: Amount | Y2: Amount | Z2: Amount | AA2: Amount
A3: For the period ended Feb 2026
A5: Revenue
A7: Gross Sales Revenue | B7: =D7+F7+H7+J7+L7+N7+P7+R7+T7+V7+X7+Z7 -> 78608.68 | D7: ='[1]Revised Jan'!$I$1 -> 51898.18 | F7: ='[1]Revised Feb'!$I$1 -> 26710.5
A8: Less : Discount | B8: =D8+F8+H8+J8+L8+N8+P8+R8+T8+V8+X8+Z8 -> -1351.5 | C8: =SUM(B7:B8) -> 77257.18 | D8: ='[1]Revised Jan'!$J$1 -> -802 | E8: =SUM(D7:D8) -> 51096.18 | F8: ='[1]Revised Feb'!$J$1 -> -549.5 | G8: =SUM(F7:F8) -> 26161 | I8: =SUM(H7:H8) -> 0 | K8: =SUM(J7:J8) -> 0 | M8: =SUM(L7:L8) -> 0 | O8: =SUM(N7:N8) -> 0 | Q8: =SUM(P7:P8) -> 0 | S8: =SUM(R7:R8) -> 0 | U8: =SUM(T7:T8) -> 0 | W8: =SUM(V7:V8) -> 0 | Y8: =SUM(X7:X8) -> 0 | AA8: =SUM(Z7:Z8) -> 0
A10: Adhoc Revenue (Events) | B10: =D10+F10+H10+J10+L10+N10+P10+R10+T10+V10+X10+Z10 -> 0 | D10: 0 | F10: 0 | H10: 0 | J10: 0 | L10: 0 | N10: 0 | P10: 0 | R10: 0 | T10: 0 | V10: 0 | X10: 0 | Z10: 0
A11: Net Sales Revenue | C11: =SUM(B7:B10) -> 77257.18 | E11: =SUM(D7:D10) -> 51096.18 | G11: =SUM(F7:F10) -> 26161 | I11: =SUM(H7:H10) -> 0 | K11: =SUM(J7:J10) -> 0 | M11: =SUM(L7:L10) -> 0 | O11: =SUM(N7:N10) -> 0 | Q11: =SUM(P7:P10) -> 0 | S11: =SUM(R7:R10) -> 0 | U11: =SUM(T7:T10) -> 0 | W11: =SUM(V7:V10) -> 0 | Y11: =SUM(X7:X10) -> 0 | AA11: =SUM(Z7:Z10) -> 0
A13: Cost of Goods Sold
A15: - Opening Stock of goods | B15: =D15+F15+H15+J15+L15+N15+P15+R15+T15+V15+X15+Z15 -> 0 | D15: ='Daily Expenses'!AI3 -> 0 | F15: ='Daily Expenses'!AI40 -> 0 | H15: ='Daily Expenses'!AI77 -> 0 | J15: ='Daily Expenses'!AI114 -> 0 | L15: ='Daily Expenses'!AI151 -> 0 | N15: ='Daily Expenses'!AI188 -> 0 | P15: ='Daily Expenses'!AI225 -> 0 | R15: ='Daily Expenses'!AI262 -> 0 | T15: ='Daily Expenses'!AI299 -> 0 | V15: ='Daily Expenses'!AI336 -> 0 | X15: ='Daily Expenses'!AI373 -> 0 | Z15: ='Daily Expenses'!AI410 -> 0
A16: - Add : Purchases | B16: =D16+F16+H16+J16+L16+N16+P16+R16+T16+V16+X16+Z16 -> 20756.12 | D16: ='Daily Expenses'!AI34 -> 17547.94 | F16: ='Daily Expenses'!AI71 -> 3208.18 | H16: ='Daily Expenses'!AI108 -> 0 | J16: ='Daily Expenses'!AI144 -> 0 | L16: ='Daily Expenses'!AI182 -> 0 | N16: ='Daily Expenses'!AI219 -> 0 | P16: ='Daily Expenses'!AI256 -> 0 | R16: ='Daily Expenses'!AI293 -> 0 | T16: ='Daily Expenses'!AI330 -> 0 | V16: ='Daily Expenses'!AI367 -> 0 | X16: ='Daily Expenses'!AI404 -> 0 | Z16: ='Daily Expenses'!AI441 -> 0
A17: Sub Total | B17: =D17+F17+H17+J17+L17+N17+P17+R17+T17+V17+X17+Z17 -> 20756.12 | D17: =SUM(D15:D16) -> 17547.94 | F17: =SUM(F15:F16) -> 3208.18 | H17: =SUM(H15:H16) -> 0 | J17: =SUM(J15:J16) -> 0 | L17: =SUM(L15:L16) -> 0 | N17: =SUM(N15:N16) -> 0 | P17: =SUM(P15:P16) -> 0 | R17: =SUM(R15:R16) -> 0 | T17: =SUM(T15:T16) -> 0 | V17: =SUM(V15:V16) -> 0 | X17: =SUM(X15:X16) -> 0 | Z17: =SUM(Z15:Z16) -> 0
A18: - Less : Closing Stock of goods | B18: 0 | D18: ='Daily Expenses'!AI36 -> 0 | F18: ='Daily Expenses'!AI73 -> 0 | H18: ='Daily Expenses'!AI110 -> 0 | J18: ='Daily Expenses'!AI147 -> 0 | L18: ='Daily Expenses'!AI184 -> 0 | N18: ='Daily Expenses'!AI221 -> 0 | P18: ='Daily Expenses'!AI258 -> 0 | R18: ='Daily Expenses'!AI295 -> 0 | T18: ='Daily Expenses'!AI332 -> 0 | V18: ='Daily Expenses'!AI369 -> 0 | X18: ='Daily Expenses'!AI406 -> 0 | Z18: ='Daily Expenses'!AI443 -> 0
A19: Cost of Goods Sold | C19: =B17-B18 -> 20756.12 | E19: =D17-D18 -> 17547.94 | G19: =F17-F18 -> 3208.18 | I19: =H17-H18 -> 0 | K19: =J17-J18 -> 0 | M19: =L17-L18 -> 0 | O19: =N17-N18 -> 0 | Q19: =P17-P18 -> 0 | S19: =R17-R18 -> 0 | U19: =T17-T18 -> 0 | W19: =V17-V18 -> 0 | Y19: =X17-X18 -> 0 | AA19: =Z17-Z18 -> 0
A21: Gross Profit | C21: =C11-C19 -> 56501.06 | E21: =E11-E19 -> 33548.24 | G21: =G11-G19 -> 22952.82 | I21: =I11-I19 -> 0 | K21: =K11-K19 -> 0 | M21: =M11-M19 -> 0 | O21: =O11-O19 -> 0 | Q21: =Q11-Q19 -> 0 | S21: =S11-S19 -> 0 | U21: =U11-U19 -> 0 | W21: =W11-W19 -> 0 | Y21: =Y11-Y19 -> 0 | AA21: =AA11-AA19 -> 0
A23: Operating Expenses
A24: - Salaries | B24: =D24+F24+H24+J24+L24+N24+P24+R24+T24+V24+X24+Z24 -> 31415.66 | D24: ='Recurring Cost'!C3 -> 13177.66 | F24: ='Recurring Cost'!D3 -> 18238 | H24: ='Recurring Cost'!E3 -> 0 | J24: ='Recurring Cost'!F3 -> 0 | L24: ='Recurring Cost'!G3 -> 0 | N24: ='Recurring Cost'!H3 -> 0 | P24: ='Recurring Cost'!I3 -> 0 | R24: ='Recurring Cost'!J3 -> 0 | T24: ='Recurring Cost'!K3 -> 0 | V24: ='Recurring Cost'!L3 -> 0 | X24: ='Recurring Cost'!M3 -> 0 | Z24: ='Recurring Cost'!N3 -> 0
A25: - Rent | B25: =D25+F25+H25+J25+L25+N25+P25+R25+T25+V25+X25+Z25 -> 0 | D25: ='Recurring Cost'!C4 -> 0 | F25: ='Recurring Cost'!D4 -> 0 | H25: ='Recurring Cost'!E4 -> 0 | J25: ='Recurring Cost'!F4 -> 0 | L25: ='Recurring Cost'!G4 -> 0 | N25: ='Recurring Cost'!H4 -> 0 | P25: ='Recurring Cost'!I4 -> 0 | R25: ='Recurring Cost'!J4 -> 0 | T25: ='Recurring Cost'!K4 -> 0 | V25: ='Recurring Cost'!L4 -> 0 | X25: ='Recurring Cost'!M4 -> 0 | Z25: ='Recurring Cost'!N4 -> 0
A26: - Utilities | B26: =D26+F26+H26+J26+L26+N26+P26+R26+T26+V26+X26+Z26 -> 8671.7 | D26: ='Recurring Cost'!C8 -> 6064.24 | F26: ='Recurring Cost'!D8 -> 2607.46 | H26: ='Recurring Cost'!E8 -> 0 | J26: ='Recurring Cost'!F8 -> 0 | L26: ='Recurring Cost'!G8 -> 0 | N26: ='Recurring Cost'!H8 -> 0 | P26: ='Recurring Cost'!I8 -> 0 | R26: ='Recurring Cost'!J8 -> 0 | T26: ='Recurring Cost'!K8 -> 0 | V26: ='Recurring Cost'!L8 -> 0 | X26: ='Recurring Cost'!M8 -> 0 | Z26: ='Recurring Cost'!N8 -> 0
A27: - Office Expenditure | B27: =D27+F27+H27+J27+L27+N27+P27+R27+T27+V27+X27+Z27 -> 1810 | D27: ='Recurring Cost'!C16 -> 230 | F27: ='Recurring Cost'!D16 -> 1580 | H27: ='Recurring Cost'!E16 -> 0 | J27: ='Recurring Cost'!F16 -> 0 | L27: ='Recurring Cost'!G16 -> 0 | N27: ='Recurring Cost'!H16 -> 0 | P27: ='Recurring Cost'!I16 -> 0 | R27: ='Recurring Cost'!J16 -> 0 | T27: ='Recurring Cost'!K16 -> 0 | V27: ='Recurring Cost'!L16 -> 0 | X27: ='Recurring Cost'!M16 -> 0 | Z27: ='Recurring Cost'!N16 -> 0
A28: - Staff Expenses | B28: =D28+F28+H28+J28+L28+N28+P28+R28+T28+V28+X28+Z28 -> 2387.5 | D28: ='Recurring Cost'!C28 -> 2287.5 | F28: ='Recurring Cost'!D28 -> 100 | H28: ='Recurring Cost'!E28 -> 0 | J28: ='Recurring Cost'!F28 -> 0 | L28: ='Recurring Cost'!G28 -> 0 | N28: ='Recurring Cost'!H28 -> 0 | P28: ='Recurring Cost'!I28 -> 0 | R28: ='Recurring Cost'!J28 -> 0 | T28: ='Recurring Cost'!K28 -> 0 | V28: ='Recurring Cost'!L28 -> 0 | X28: ='Recurring Cost'!M28 -> 0 | Z28: ='Recurring Cost'!N28 -> 0
A29: - Sundry Expenses | B29: =D29+F29+H29+J29+L29+N29+P29+R29+T29+V29+X29+Z29 -> 5240 | D29: ='Recurring Cost'!C39 -> 2500 | F29: ='Recurring Cost'!D39 -> 2740 | H29: ='Recurring Cost'!E39 -> 0 | J29: ='Recurring Cost'!F39 -> 0 | L29: ='Recurring Cost'!G39 -> 0 | N29: ='Recurring Cost'!H39 -> 0 | P29: ='Recurring Cost'!I39 -> 0 | R29: ='Recurring Cost'!J39 -> 0 | T29: ='Recurring Cost'!K39 -> 0 | V29: ='Recurring Cost'!L39 -> 0 | X29: ='Recurring Cost'!M39 -> 0 | Z29: ='Recurring Cost'!N39 -> 0
A30: - Taxes | B30: =D30+F30+H30+J30+L30+N30+P30+R30+T30+V30+X30+Z30 -> 3628.53 | D30: ='Recurring Cost'!C45 -> 2385.24 | F30: ='Recurring Cost'!D45 -> 1243.29 | H30: ='Recurring Cost'!E45 -> 0 | J30: ='Recurring Cost'!F45 -> 0 | L30: ='Recurring Cost'!G45 -> 0 | N30: ='Recurring Cost'!H45 -> 0 | P30: ='Recurring Cost'!I45 -> 0 | R30: ='Recurring Cost'!J45 -> 0 | T30: ='Recurring Cost'!K45 -> 0 | V30: ='Recurring Cost'!L45 -> 0 | X30: ='Recurring Cost'!M45 -> 0 | Z30: ='Recurring Cost'!N45 -> 0
A32: Total Expenses | C32: =SUM(B24:B30) -> 53153.39 | E32: =SUM(D24:D30) -> 26644.64 | G32: =SUM(F24:F30) -> 26508.75 | I32: =SUM(H24:H30) -> 0 | K32: =SUM(J24:J30) -> 0 | M32: =SUM(L24:L30) -> 0 | O32: =SUM(N24:N30) -> 0 | Q32: =SUM(P24:P30) -> 0 | S32: =SUM(R24:R30) -> 0 | U32: =SUM(T24:T30) -> 0 | W32: =SUM(V24:V30) -> 0 | Y32: =SUM(X24:X30) -> 0 | AA32: =SUM(Z24:Z30) -> 0
A34: Net Profit (EBIT) | C34: =C21-C32 -> 3347.67 | E34: =E21-E32 -> 6903.6 | G34: =G21-G32 -> -3555.93 | I34: =I21-I32 -> 0 | K34: =K21-K32 -> 0 | M34: =M21-M32 -> 0 | O34: =O21-O32 -> 0 | Q34: =Q21-Q32 -> 0 | S34: =S21-S32 -> 0 | U34: =U21-U32 -> 0 | W34: =W21-W32 -> 0 | Y34: =Y21-Y32 -> 0 | AA34: =AA21-AA32 -> 0
A35: - Interest | B35: 0 | D35: 0 | F35: 0 | H35: 0 | J35: 0 | L35: 0 | N35: 0 | P35: 0 | R35: 0 | T35: 0 | V35: 0 | X35: 0 | Z35: 0
A36: - Taxes | B36: 0 | D36: 0 | F36: 0 | H36: 0 | J36: 0 | L36: 0 | N36: 0 | P36: 0 | R36: 0 | T36: 0 | V36: 0 | X36: 0 | Z36: 0
A37: Total of Interest & Taxes | C37: =SUM(B35:B36) -> 0 | E37: =SUM(D35:D36) -> 0 | G37: =SUM(F35:F36) -> 0 | I37: =SUM(H35:H36) -> 0 | K37: =SUM(J35:J36) -> 0 | M37: =SUM(L35:L36) -> 0 | O37: =SUM(N35:N36) -> 0 | Q37: =SUM(P35:P36) -> 0 | S37: =SUM(R35:R36) -> 0 | U37: =SUM(T35:T36) -> 0 | W37: =SUM(V35:V36) -> 0 | Y37: =SUM(X35:X36) -> 0 | AA37: =SUM(Z35:Z36) -> 0
A39: Net Profit after Interest & Tax | B39: =SUM(B34:B36) -> 0 | C39: =C34-C37 -> 3347.67 | D39: =SUM(D34:D36) -> 0 | E39: =E34-E37 -> 6903.6 | F39: =SUM(F34:F36) -> 0 | G39: =G34-G37 -> -3555.93 | H39: =SUM(H34:H36) -> 0 | I39: =I34-I37 -> 0 | J39: =SUM(J34:J36) -> 0 | K39: =K34-K37 -> 0 | L39: =SUM(L34:L36) -> 0 | M39: =M34-M37 -> 0 | N39: =SUM(N34:N36) -> 0 | O39: =O34-O37 -> 0 | P39: =SUM(P34:P36) -> 0 | Q39: =Q34-Q37 -> 0 | R39: =SUM(R34:R36) -> 0 | S39: =S34-S37 -> 0 | T39: =SUM(T34:T36) -> 0 | U39: =U34-U37 -> 0 | V39: =SUM(V34:V36) -> 0 | W39: =W34-W37 -> 0 | X39: =SUM(X34:X36) -> 0 | Y39: =Y34-Y37 -> 0 | Z39: =SUM(Z34:Z36) -> 0 | AA39: =AA34-AA37 -> 0

Sheet Daily Expenses
A2: Sr. No. | B2: Description of goods Purchased | C2: 1 | D2: 2 | E2: 3 | F2: 4 | G2: 5 | H2: 6 | I2: 7 | J2: 8 | K2: 9 | L2: 10 | M2: 11 | N2: 12 | O2: 13 | P2: 14 | Q2: 15 | R2: 16 | S2: 17 | T2: 18 | U2: 19 | V2: 20 | W2: 21 | X2: 22 | Y2: 23 | Z2: 24 | AA2: 25 | AB2: 26 | AC2: 27 | AD2: 28 | AE2: 29 | AF2: 30 | AG2: 31 | AH2: Online | AI2: Total
B3: Opening stock of goods | C3: 0 | D3: 0 | E3: 0 | F3: 0 | G3: 0 | H3: 0 | I3: 0 | J3: 0 | K3: 0 | L3: 0 | M3: 0 | N3: 0 | O3: 0 | P3: 0 | Q3: 0 | R3: 0 | S3: 0 | T3: 0 | U3: 0 | V3: 0 | W3: 0 | X3: 0 | Y3: 0 | Z3: 0 | AA3: 0 | AB3: 0 | AC3: 0 | AD3: 0 | AE3: 0 | AF3: 0 | AG3: 0 | AH3: 0 | AI3: =SUM(C3:AH3) -> 0
A4: 1 | B4: ANWAR FLOUR MILL | AH4: 3578.65 | AI4: =SUM(C4:AH4) -> 3578.65
A5: 2 | B5: SPOT PACK | AH5: 1975.74 | AI5: =SUM(C5:AH5) -> 1975.74
A6: 3 | B6: SHINE DAIRY | AH6: 1351.35 | AI6: =SUM(C6:AH6) -> 1351.35
A7: 4 | B7: AL MADINA | D7: 12 | E7: 14 | F7: 50 | L7: 18.25 | M7: 50 | T7: 19 | V7: 3.25 | X7: 110 | Y7: 224.75 | Z7: 236.5 | AA7: 50 | AB7: 40.5 | AI7: =SUM(C7:AH7) -> 828.25
A8: 5 | B8: VIVA SUPERMARKET | E8: 12 | K8: 22 | L8: 10 | M8: 16 | V8: 10 | X8: 200 | Y8: 116 | Z8: 181.75 | AD8: 10 | AI8: =SUM(C8:AH8) -> 577.75
A9: 6 | B9: ADIL SUPERMARKET | C9: 142 | D9: 46.25 | H9: 18 | U9: 46.25 | X9: 139 | AC9: 142 | AI9: =SUM(C9:AH9) -> 533.5
A10: 7 | B10: CHUNILAL PURSHOTTAM | AH10: 395 | AI10: =SUM(C10:AH10) -> 395
A11: 8 | B11: NFPC | C11: 34.25 | D11: 34.25 | K11: 34.25 | M11: 34.25 | P11: 34.25 | T11: 34.25 | W11: 34.25 | Y11: 34.25 | Z11: 34.25 | AE11: 34.25 | AG11: 34.25 | AI11: =SUM(C11:AH11) -> 376.75
A12: 9 | B12: YOUSUF PLASTIC HAMAD | AH12: 349.7 | AI12: =SUM(C12:AH12) -> 349.7
A13: 10 | B13: SWADESH | C13: 47.5 | D13: 10.5 | F13: 10.5 | H13: 34.25 | J13: 10.5 | K13: 10.5 | M13: 10.5 | R13: 10.5 | S13: 31.75 | V13: 10.5 | W13: 10.5 | X13: 10.5 | Z13: 10.5 | AA13: 10.5 | AD13: 44.5 | AG13: 10.5 | AI13: =SUM(C13:AH13) -> 284
A14: 11 | B14: MODERN KEY TRENDING L.L.C | D14: 136.75 | X14: 140 | AI14: =SUM(C14:AH14) -> 276.75
A15: 12 | B15: ALI AL SAKIT | AH15: 200.25 | AI15: =SUM(C15:AH15) -> 200.25
A16: 13 | B16: FALCON GLOBAL LLC. | J16: 139 | AI16: =SUM(C16:AH16) -> 139
A17: 14 | B17: DUBAI REFRESHMENT(P.J.S.C.) | G17: 43 | AC17: 43 | AE17: 27 | AI17: =SUM(C17:AH17) -> 113
A18: 15 | B18: JOSHI FHARSAN | K18: 37.75 | X18: 36.75 | AB18: 36.75 | AI18: =SUM(C18:AH18) -> 111.25
A19: 16 | B19: ESSA GROCERY | L19: 5 | AI19: =SUM(C19:AH19) -> 5
A20: 17 | B20: SHIELD GAS | P20: 3192 | AI20: =SUM(C20:AH20) -> 3192
A21: 18 | B21: VEGETABLE | K21: 705 | P21: 636.75 | AI21: =SUM(C21:AH21) -> 1341.75
A22: 19 | B22: Day To Day | C22: 0 | D22: 0 | E22: 0 | F22: 0 | G22: 0 | H22: 0 | I22: 0 | J22: 0 | K22: 0 | L22: 0 | M22: 0 | N22: 0 | O22: 0 | P22: 0 | Q22: 0 | R22: 0 | S22: 0 | T22: 0 | U22: 0 | V22: 0 | W22: 0 | X22: 0 | Y22: 0 | Z22: 0 | AA22: 0 | AB22: 0 | AC22: 0 | AD22: 12 | AE22: 0 | AF22: 0 | AG22: 0 | AH22: 0 | AI22: =SUM(C22:AH22) -> 12
A23: 20 | B23: Extra Item | D23: 5 | F23: 80 | H23: 20 | S23: 20 | W23: 39 | Z23: 35 | AC23: 20 | AI23: =SUM(C23:AH23) -> 219
A24: 21 | B24: Greas Treap | P24: 200 | AG24: 200 | AI24: =SUM(C24:AH24) -> 400
A25: 22 | B25: NAZIMUDDIN BUILDING | D25: 5 | K25: 13.5 | AF25: 20 | AI25: =SUM(C25:AH25) -> 38.5
A26: 23 | B26: MR.COPY | R26: 511.25 | X26: 2 | Y26: 1 | AI26: =SUM(C26:AH26) -> 514.25
A27: 24 | B27: ROYAL SWEET BAKERY | Y27: 294 | Z27: 336 | AI27: =SUM(C27:AH27) -> 630
A28: 25 | B28: WEST ZONE | Y28: 70.5 | AI28: =SUM(C28:AH28) -> 70.5
A29: 26 | B29: JASR AL TAWER | Z29: 13 | AC29: 21 | AI29: =SUM(C29:AH29) -> 34
A30: 27 | C30: 0 | D30: 0 | E30: 0 | F30: 0 | G30: 0 | H30: 0 | I30: 0 | J30: 0 | K30: 0 | L30: 0 | M30: 0 | N30: 0 | O30: 0 | P30: 0 | Q30: 0 | R30: 0 | S30: 0 | T30: 0 | U30: 0 | V30: 0 | W30: 0 | X30: 0 | Y30: 0 | Z30: 0 | AA30: 0 | AB30: 0 | AC30: 0 | AD30: 0 | AE30: 0 | AF30: 0 | AG30: 0 | AH30: 0 | AI30: =SUM(C30:AH30) -> 0
A31: 28 | C31: 0 | D31: 0 | E31: 0 | F31: 0 | G31: 0 | H31: 0 | I31: 0 | J31: 0 | K31: 0 | L31: 0 | M31: 0 | N31: 0 | O31: 0 | P31: 0 | Q31: 0 | R31: 0 | S31: 0 | T31: 0 | U31: 0 | V31: 0 | W31: 0 | X31: 0 | Y31: 0 | Z31: 0 | AA31: 0 | AB31: 0 | AC31: 0 | AD31: 0 | AE31: 0 | AF31: 0 | AG31: 0 | AH31: 0 | AI31: =SUM(C31:AH31) -> 0
A32: 29 | C32: 0 | D32: 0 | E32: 0 | F32: 0 | G32: 0 | H32: 0 | I32: 0 | J32: 0 | K32: 0 | L32: 0 | M32: 0 | N32: 0 | O32: 0 | P32: 0 | Q32: 0 | R32: 0 | S32: 0 | T32: 0 | U32: 0 | V32: 0 | W32: 0 | X32: 0 | Y32: 0 | Z32: 0 | AA32: 0 | AB32: 0 | AC32: 0 | AD32: 0 | AE32: 0 | AF32: 0 | AG32: 0 | AH32: 0 | AI32: =SUM(C32:AH32) -> 0
A33: 30 | C33: 0 | D33: 0 | E33: 0 | F33: 0 | G33: 0 | H33: 0 | I33: 0 | J33: 0 | K33: 0 | L33: 0 | M33: 0 | N33: 0 | O33: 0 | P33: 0 | Q33: 0 | R33: 0 | S33: 0 | T33: 0 | U33: 0 | V33: 0 | W33: 0 | X33: 0 | Y33: 0 | Z33: 0 | AA33: 0 | AB33: 0 | AC33: 0 | AD33: 0 | AE33: 0 | AF33: 0 | AG33: 0 | AH33: 0 | AI33: =SUM(C33:AH33) -> 0
B34: Cost of Goods Purchased | C34: =SUM(C4:C33) -> 223.75 | D34: =SUM(D4:D33) -> 249.75 | E34: =SUM(E4:E33) -> 26 | F34: =SUM(F4:F33) -> 140.5 | G34: =SUM(G4:G33) -> 43 | H34: =SUM(H4:H33) -> 72.25 | I34: =SUM(I4:I33) -> 0 | J34: =SUM(J4:J33) -> 149.5 | ... AI34: =SUM(AI4:AI33) -> 17547.94
B35: Sub Total | C35: =C34+C3 -> 223.75 | D35: =D34+D3 -> 249.75 | E35: =E34+E3 -> 26 | F35: =F34+F3 -> 140.5 | G35: =G34+G3 -> 43 | H35: =H34+H3 -> 72.25 | I35: =I34+I3 -> 0 | J35: =J34+J3 -> 149.5 | ... AI35: =AI34+AI3 -> 17547.94
B36: Closing stock of goods | C36: 0 | D36: 0 | E36: 0 | F36: 0 | G36: 0 | H36: 0 | I36: 0 | J36: 0 | K36: 0 | L36: 0 | M36: 0 | N36: 0 | O36: 0 | P36: 0 | Q36: 0 | R36: 0 | S36: 0 | T36: 0 | U36: 0 | V36: 0 | W36: 0 | X36: 0 | Y36: 0 | Z36: 0 | AA36: 0 | AB36: 0 | AC36: 0 | AD36: 0 | AE36: 0 | AF36: 0 | AG36: 0 | AH36: 0 | AI36: =SUM(C36:AH36) -> 0
B38: COST OF GOODS SOLD - Jan | C38: =C35-C36 -> 223.75 | D38: =D35-D36 -> 249.75 | E38: =E35-E36 -> 26 | F38: =F35-F36 -> 140.5 | G38: =G35-G36 -> 43 | H38: =H35-H36 -> 72.25 | I38: =I35-I36 -> 0 | J38: =J35-J36 -> 149.5 | ... AI38: =AI35-AI36 -> 17547.94
B40: Opening stock of goods | C40: =C36 -> 0 | D40: =D36 -> 0 | E40: =E36 -> 0 | F40: =F36 -> 0 | G40: =G36 -> 0 | H40: =H36 -> 0 | I40: =I36 -> 0 | J40: =J36 -> 0 | ... AH40: =AH36 -> 0 | AI40: =SUM(C40:AH40) -> 0
A41: 1 | B41: ADIL SUPERMARKET | O41: 209.75 | P41: 27.75 | AI41: =SUM(C41:AH41) -> 237.5
A42: 2 | B42: AL MADINA | C42: 59.75 | D42: 30.25 | I42: 11 | K42: 50 | P42: 6 | Q42: 36.75 | AI42: =SUM(C42:AH42) -> 193.75
A43: 3 | B43: ALI AL SAKIT | AI43: =SUM(C43:AH43) -> 0
...

Sheet Recurring Cost
A2: Sr. No. | B2: Details of Cost | C2: Jan | D2: Feb | E2: Mar | F2: Apr | G2: May | H2: Jun | I2: Jul | J2: Aug | K2: Sep | L2: Oct | M2: Nov | N2: Dec | O2: Total
A3: 1 | B3: Salaries | C3: =12366.66+811 -> 13177.66 | D3: =7000+11238 -> 18238 | O3: =SUM(C3:N3) -> 31415.66
A4: 2 | B4: Rent | C4: =SUBTOTAL(9,C5:C6) -> 0 | D4: =SUBTOTAL(9,D5:D6) -> 0 | E4: =SUBTOTAL(9,E5:E6) -> 0 | F4: =SUBTOTAL(9,F5:F6) -> 0 | G4: =SUBTOTAL(9,G5:G6) -> 0 | H4: =SUBTOTAL(9,H5:H6) -> 0 | I4: =SUBTOTAL(9,I5:I6) -> 0 | J4: =SUBTOTAL(9,J5:J6) -> 0 | ... N4: =SUBTOTAL(9,N5:N6) -> 0 | O4: =SUM(C4:N4) -> 0
B5: - Sai Dham | O5: =SUM(C5:N5) -> 0
B6: - Staff Room | O6: =SUM(C6:N6) -> 0
A8: 3 | B8: Utilities | C8: =SUBTOTAL(9,C9:C14) -> 6064.24 | D8: =SUBTOTAL(9,D9:D14) -> 2607.46 | E8: =SUBTOTAL(9,E9:E14) -> 0 | F8: =SUBTOTAL(9,F9:F14) -> 0 | G8: =SUBTOTAL(9,G9:G14) -> 0 | H8: =SUBTOTAL(9,H9:H14) -> 0 | I8: =SUBTOTAL(9,I9:I14) -> 0 | J8: =SUBTOTAL(9,J9:J14) -> 0 | ... O8: =SUBTOTAL(9,O9:O14) -> 8671.7
A9: i | B9: DEWA Expenses | C9: =SUBTOTAL(9,C10:C11) -> 4911.34 | D9: =SUBTOTAL(9,D10:D11) -> 2407.46 | E9: =SUBTOTAL(9,E10:E11) -> 0 | F9: =SUBTOTAL(9,F10:F11) -> 0 | G9: =SUBTOTAL(9,G10:G11) -> 0 | H9: =SUBTOTAL(9,H10:H11) -> 0 | I9: =SUBTOTAL(9,I10:I11) -> 0 | J9: =SUBTOTAL(9,J10:J11) -> 0 | ... O9: =SUBTOTAL(9,O10:O11) -> 7318.8
B10: - Sai Dham | C10: 2005.06 | D10: 1907.46 | O10: =SUM(C10:N10) -> 3912.52
B11: - Staff Room | C11: 2906.28 | D11: 500 | O11: =SUM(C11:N11) -> 3406.28
A12: ii | B12: DU Wifi | C12: =SUBTOTAL(9,C13:C14) -> 1152.9 | D12: =SUBTOTAL(9,D13:D14) -> 200 | E12: =SUBTOTAL(9,E13:E14) -> 0 | F12: =SUBTOTAL(9,F13:F14) -> 0 | G12: =SUBTOTAL(9,G13:G14) -> 0 | H12: =SUBTOTAL(9,H13:H14) -> 0 | I12: =SUBTOTAL(9,I13:I14) -> 0 | J12: =SUBTOTAL(9,J13:J14) -> 0 | ... O12: =SUBTOTAL(9,O13:O14) -> 1352.9
B13: - Sai Dham | C13: =[2]JANUARY!$AI$26 -> 1152.9 | O13: =SUM(C13:N13) -> 1152.9
B14: - Staff Room | D14: 200 | O14: =SUM(C14:N14) -> 200
A16: 4 | B16: Office Expenditure | C16: =SUBTOTAL(9,C17:C26) -> 230 | D16: =SUBTOTAL(9,D17:D26) -> 1580 | E16: =SUBTOTAL(9,E17:E26) -> 0 | F16: =SUBTOTAL(9,F17:F26) -> 0 | G16: =SUBTOTAL(9,G17:G26) -> 0 | H16: =SUBTOTAL(9,H17:H26) -> 0 | I16: =SUBTOTAL(9,I17:I26) -> 0 | J16: =SUBTOTAL(9,J17:J26) -> 0 | ... O16: =SUBTOTAL(9,O17:O26) -> 1810
A17: i | B17: Maintenance | C17: 100 | D17: =130+450 -> 580 | O17: =SUM(C17:N17) -> 680
A18: ii | B18: Pest Control | C18: 100 | O18: =SUM(C18:N18) -> 100
A19: iii | B19: Flowers | C19: 10 | O19: =SUM(C19:N19) -> 10
A20: iv | B20: Knife Sharpening | C20: 20 | O20: =SUM(C20:N20) -> 20
A21: v | B21: Sign Board | D21: 1000 | O21: =SUM(C21:N21) -> 1000
O22: =SUM(C22:N22) -> 0
O23: =SUM(C23:N23) -> 0
O24: =SUM(C24:N24) -> 0
O25: =SUM(C25:N25) -> 0
O26: =SUM(C26:N26) -> 0
A28: 5 | B28: Staff Expenses | C28: =SUBTOTAL(9,C29:C37) -> 2287.5 | D28: =SUBTOTAL(9,D29:D37) -> 100 | E28: =SUBTOTAL(9,E29:E37) -> 0 | F28: =SUBTOTAL(9,F29:F37) -> 0 | G28: =SUBTOTAL(9,G29:G37) -> 0 | H28: =SUBTOTAL(9,H29:H37) -> 0 | I28: =SUBTOTAL(9,I29:I37) -> 0 | J28: =SUBTOTAL(9,J29:J37) -> 0 | ... O28: =SUBTOTAL(9,O29:O37) -> 2387.5
A29: i | B29: Staff Tips | C29: 150 | O29: =SUM(C29:N29) -> 150
A30: ii | B30: Conveyance (Taxi fare) | C30: 737.5 | D30: 100 | O30: =SUM(C30:N30) -> 837.5
A31: iii | B31: Ravi Naresh - Visa Exchange | C31: 100 | O31: =SUM(C31:N31) -> 100
A32: iv | B32: Sravan Visa Renewal | C32: 1300 | O32: =SUM(C32:N32) -> 1300
O33: =SUM(C33:N33) -> 0
O34: =SUM(C34:N34) -> 0
O35: =SUM(C35:N35) -> 0
O36: =SUM(C36:N36) -> 0
O37: =SUM(C37:N37) -> 0
A39: 6 | B39: Sundry Expenses | C39: =SUBTOTAL(9,C40:C43) -> 2500 | D39: =SUBTOTAL(9,D40:D43) -> 2740 | E39: =SUBTOTAL(9,E40:E43) -> 0 | F39: =SUBTOTAL(9,F40:F43) -> 0 | G39: =SUBTOTAL(9,G40:G43) -> 0 | H39: =SUBTOTAL(9,H40:H43) -> 0 | I39: =SUBTOTAL(9,I40:I43) -> 0 | J39: =SUBTOTAL(9,J40:J43) -> 0 | ... O39: =SUBTOTAL(9,O40:O43) -> 5240
A40: i | B40: Budhilal Holiday Settlement | C40: 2000 | O40: =SUM(C40:N40) -> 2000
A41: ii | B41: ALFAZ AHEMAD ( december , jan) | D41: 2240 | O41: =SUM(C41:N41) -> 2240
A42: iii | B42: Cheque Bounce Charges | C42: 500 | D42: 500 | O42: =SUM(C42:N42) -> 1000
A43: iv | O43: =SUM(C43:N43) -> 0
A45: 7 | B45: Taxes | C45: ='[1]Revised Jan'!$L$1 -> 2385.24 | D45: ='[1]Revised Feb'!$L$1 -> 1243.29 | O45: =SUM(C45:N45) -> 3628.53
A46: 8 | O46: =SUM(C46:N46) -> 0
...

Sheet Balance Sheet
A2: Company : Sai Dham
A3: BALANCE SHEET
A4: For the year ended 31st Dec 2025
A5: Assets | B5: Amount | D5: Liabilities & Equity | E5: Amount
A7: Current Assets | D7: Current Liabilities
A9: Cash | D9: Accounts Payable
D10: Short-term debt
A13: Accounts Receivable | D13: Long-term Liabilities
D14: Long-term Debt
A16: Inventory
A19: Non-Current (Fixed Assets) | D19: Shareholders Equity | E19: 300000
A21: Furniture & Fixture | D21: Common Stock/ Capital
D22: Retained Earnings
B25: =SUM(B7:B24) -> 0 | E25: =SUM(E7:E24) -> 300000
